<mujoco model="ur5e_x2">
  <compiler angle="radian" autolimits="true" meshdir="/home/adenzler/git/mujoco_menagerie"/>

  <option integrator="implicitfast"/>

  <default>
    <default class="ur5e">
      <default class="visual">
        <geom type="mesh" contype="0" conaffinity="0" group="2"/>
      </default>
      <default class="collision">
        <geom type="capsule" group="3"/>
        <default class="eef_collision">
          <geom type="cylinder"/>
        </default>
      </default>
      <joint axis="0 1 0" range="-6.28319 6.28319"/>
      <default class="joint_limited">
        <joint range="-3.1415 3.1415"/>
      </default>
      <default class="position">
        <position ctrlrange="-6.2831 6.2831" kp="2000" kv="200" forcerange="-150 150"/>
        <default class="position_limited">
          <position ctrlrange="-3.1415 3.1415"/>
        </default>
        <default class="position_small">
          <position kp="500" kv="50" forcerange="-28 28"/>
        </default>
      </default>
    </default>
    <default class="2f85">
      <mesh scale="0.001 0.001 0.001"/>
      <general biastype="affine"/>
      <site type="sphere" rgba="0.9 0.9 0.9 1" size="0.005" group="4"/>
      <joint axis="1 0 0"/>
      <default class="driver">
        <joint range="0 0.8" armature="0.005" damping="0.1" solimplimit="0.95 0.99 0.001" solreflimit="0.005 1"/>
      </default>
      <default class="follower">
        <joint range="-0.872664 0.872664" pos="0 -0.018 0.0065" solimplimit="0.95 0.99 0.001" solreflimit="0.005 1"/>
      </default>
      <default class="spring_link">
        <joint range="-0.29670597283 0.8" stiffness="0.05" springref="2.62" damping="0.00125"/>
      </default>
      <default class="coupler">
        <joint range="-1.57 0" solimplimit="0.95 0.99 0.001" solreflimit="0.005 1"/>
      </default>
      <default class="2f85/visual">
        <geom type="mesh" contype="0" conaffinity="0" group="2"/>
      </default>
      <default class="2f85/collision">
        <geom type="mesh" group="3"/>
        <default class="pad_box1">
          <geom mass="0" type="box" pos="0 -0.0026 0.028125" size="0.011 0.004 0.009375" friction="0.7"
            solimp="0.95 0.99 0.001" solref="0.004 1" priority="1" rgba="0.55 0.55 0.55 1"/>
        </default>
        <default class="pad_box2">
          <geom mass="0" type="box" pos="0 -0.0026 0.009375" size="0.011 0.004 0.009375" friction="0.6"
            solimp="0.95 0.99 0.001" solref="0.004 1" priority="1" rgba="0.45 0.45 0.45 1"/>
        </default>
      </default>
    </default>
  </default>

  <asset>
    <material name="black" rgba="0.033 0.033 0.033 1"/>
    <material name="jointgray" rgba="0.278 0.278 0.278 1"/>
    <material name="linkgray" rgba="0.82 0.82 0.82 1"/>
    <material name="urblue" rgba="0.49 0.678 0.8 1"/>
    <material name="white" rgba="1 1 1 1"/>
    <material name="off_white" rgba="0.901961 0.921569 0.929412 1"/>
    <material name="dark_grey" rgba="0.25 0.25 0.25 1"/>
    <material name="green" rgba="0 1 0 1"/>
    <material name="light_blue" rgba="0.039216 0.541176 0.780392 1"/>
    <material name="metal" rgba="0.58 0.58 0.58 1"/>
    <material name="silicone" rgba="0.1882 0.1882 0.1882 1"/>
    <material name="gray" rgba="0.4627 0.4627 0.4627 1"/>
    <material name="2f85/black" rgba="0.149 0.149 0.149 1"/>

    <mesh file="universal_robots_ur5e/assets/base_0.obj"/>
    <mesh file="universal_robots_ur5e/assets/base_1.obj"/>
    <mesh file="universal_robots_ur5e/assets/shoulder_0.obj"/>
    <mesh file="universal_robots_ur5e/assets/shoulder_1.obj"/>
    <mesh file="universal_robots_ur5e/assets/shoulder_2.obj"/>
    <mesh file="universal_robots_ur5e/assets/upperarm_0.obj"/>
    <mesh file="universal_robots_ur5e/assets/upperarm_1.obj"/>
    <mesh file="universal_robots_ur5e/assets/upperarm_2.obj"/>
    <mesh file="universal_robots_ur5e/assets/upperarm_3.obj"/>
    <mesh file="universal_robots_ur5e/assets/forearm_0.obj"/>
    <mesh file="universal_robots_ur5e/assets/forearm_1.obj"/>
    <mesh file="universal_robots_ur5e/assets/forearm_2.obj"/>
    <mesh file="universal_robots_ur5e/assets/forearm_3.obj"/>
    <mesh file="universal_robots_ur5e/assets/wrist1_0.obj"/>
    <mesh file="universal_robots_ur5e/assets/wrist1_1.obj"/>
    <mesh file="universal_robots_ur5e/assets/wrist1_2.obj"/>
    <mesh file="universal_robots_ur5e/assets/wrist2_0.obj"/>
    <mesh file="universal_robots_ur5e/assets/wrist2_1.obj"/>
    <mesh file="universal_robots_ur5e/assets/wrist2_2.obj"/>
    <mesh file="universal_robots_ur5e/assets/wrist3.obj"/>

    <mesh class="2f85" file="robotiq_2f85/assets/base_mount.stl"/>
    <mesh class="2f85" file="robotiq_2f85/assets/base.stl"/>
    <mesh class="2f85" file="robotiq_2f85/assets/driver.stl"/>
    <mesh class="2f85" file="robotiq_2f85/assets/coupler.stl"/>
    <mesh class="2f85" file="robotiq_2f85/assets/follower.stl"/>
    <mesh class="2f85" file="robotiq_2f85/assets/pad.stl"/>
    <mesh class="2f85" file="robotiq_2f85/assets/silicone_pad.stl"/>
    <mesh class="2f85" file="robotiq_2f85/assets/spring_link.stl"/>
  </asset>

  <worldbody>
    <!-- Robot 1 -->
    <body name="ur5e_1/base" quat="1 0 0 1" childclass="ur5e">
      <inertial mass="4" pos="0 0 0" diaginertia="0.00443333156 0.00443333156 0.0072"/>
      <geom mesh="base_0" material="black" class="visual"/>
      <geom mesh="base_1" material="jointgray" class="visual"/>
      <body name="shoulder_link_1" pos="0 0 0.163">
        <inertial mass="3.7" pos="0 0 0" diaginertia="0.0102675 0.0102675 0.00666"/>
        <joint name="shoulder_pan_joint_1" axis="0 0 1"/>
        <geom class="collision" size="0.06 0.06" pos="0 0 -0.04"/>
        <body name="upper_arm_link_1" pos="0 0.138 0" quat="1 0 1 0">
          <inertial mass="8.393" pos="0 0 0.2125" diaginertia="0.133886 0.133886 0.0151074"/>
          <joint name="shoulder_lift_joint_1"/>
          <geom class="collision" pos="0 -0.04 0" quat="1 1 0 0" size="0.06 0.06"/>
          <geom class="collision" size="0.05 0.2" pos="0 0 0.2"/>
          <body name="forearm_link_1" pos="0 -0.131 0.425">
            <inertial mass="2.275" pos="0 0 0.196" diaginertia="0.0311796 0.0311796 0.004095"/>
            <joint name="elbow_joint_1" class="joint_limited"/>
            <geom class="collision" pos="0 0.08 0" quat="1 1 0 0" size="0.055 0.06"/>
            <geom class="collision" size="0.038 0.19" pos="0 0 0.2"/>
            <body name="wrist_1_link_1" pos="0 0 0.392" quat="1 0 1 0">
              <inertial mass="1.219" pos="0 0.127 0" diaginertia="0.0025599 0.0025599 0.0021942"/>
              <joint name="wrist_1_joint_1"/>
              <geom class="collision" pos="0 0.05 0" quat="1 1 0 0" size="0.04 0.07"/>
              <body name="wrist_2_link_1" pos="0 0.127 0">
                <inertial mass="1.219" pos="0 0 0.1" diaginertia="0.0025599 0.0025599 0.0021942"/>
                <joint name="wrist_2_joint_1" axis="0 0 1"/>
                <geom class="collision" size="0.04 0.06" pos="0 0 0.04"/>
                <geom class="collision" pos="0 0.02 0.1" quat="1 1 0 0" size="0.04 0.04"/>
                <body name="wrist_3_link_1" pos="0 0 0.1">
                  <inertial mass="0.1879" pos="0 0.0771683 0" quat="1 0 0 1"
                    diaginertia="0.000132134 9.90863e-05 9.90863e-05"/>
                  <joint name="wrist_3_joint_1"/>
                  <geom class="eef_collision" pos="0 0.08 0" quat="1 1 0 0" size="0.04 0.02"/>
                  <body name="attachment_1" pos="0 0.1 0" quat="-1 1 1 1">
                    <body name="base_mount_1" quat="1 0 0 1" childclass="2f85">
                      <geom class="2f85/collision" mesh="base_mount"/>
                      <body name="gripper_base_1" pos="0 0 0.0038" quat="1 0 0 -1">
                        <inertial mass="0.777441" pos="0 -2.70394e-05 0.0354675" quat="1 -0.00152849 0 0"
                          diaginertia="0.000260285 0.000225381 0.000152708"/>
                        <geom class="2f85/collision" mesh="base"/>
                        <body name="right_driver_1" pos="0 0.0306011 0.054904">
                          <inertial mass="0.00899563" pos="2.96931e-12 0.0177547 0.00107314"
                            quat="0.681301 0.732003 0 0" diaginertia="1.72352e-06 1.60906e-06 3.22006e-07"/>
                          <joint name="right_driver_joint_1" class="driver"/>
                          <geom class="2f85/collision" mesh="driver"/>
                          <body name="right_coupler_1" pos="0 0.0315 -0.0041">
                            <inertial mass="0.0140974" pos="0 0.00301209 0.0232175"
                              quat="0.705636 -0.0455904 0.0455904 0.705636"
                              diaginertia="4.16206e-06 3.52216e-06 8.88131e-07"/>
                            <joint name="right_coupler_joint_1" class="coupler"/>
                            <geom class="2f85/collision" mesh="coupler"/>
                          </body>
                        </body>
                        <body name="right_spring_link_1" pos="0 0.0132 0.0609">
                          <inertial mass="0.0221642" pos="-8.65005e-09 0.0181624 0.0212658"
                            quat="0.663403 -0.244737 0.244737 0.663403"
                            diaginertia="8.96853e-06 6.71733e-06 2.63931e-06"/>
                          <joint name="right_spring_link_joint_1" class="spring_link"/>
                          <geom class="2f85/collision" mesh="spring_link"/>
                          <body name="right_follower_1" pos="0 0.055 0.0375">
                            <inertial mass="0.0125222" pos="0 -0.011046 0.0124786" quat="1 0.1664 0 0"
                              diaginertia="2.67415e-06 2.4559e-06 6.02031e-07"/>
                            <joint name="right_follower_joint_1" class="follower"/>
                            <geom class="2f85/collision" mesh="follower"/>
                            <body name="right_pad_1" pos="0 -0.0189 0.01352">
                              <geom class="pad_box1" name="right_pad1_1"/>
                              <geom class="pad_box2" name="right_pad2_1"/>
                              <inertial mass="0.0035" pos="0 -0.0025 0.0185" quat="0.707107 0 0 0.707107"
                                diaginertia="4.73958e-07 3.64583e-07 1.23958e-07"/>
                            </body>
                          </body>
                        </body>
                        <body name="left_driver_1" pos="0 -0.0306011 0.054904" quat="0 0 0 1">
                          <inertial mass="0.00899563" pos="0 0.0177547 0.00107314" quat="0.681301 0.732003 0 0"
                            diaginertia="1.72352e-06 1.60906e-06 3.22006e-07"/>
                          <joint name="left_driver_joint_1" class="driver"/>
                          <geom class="2f85/collision" mesh="driver"/>
                          <body name="left_coupler_1" pos="0 0.0315 -0.0041">
                            <inertial mass="0.0140974" pos="0 0.00301209 0.0232175"
                              quat="0.705636 -0.0455904 0.0455904 0.705636"
                              diaginertia="4.16206e-06 3.52216e-06 8.88131e-07"/>
                            <joint name="left_coupler_joint_1" class="coupler"/>
                            <geom class="2f85/collision" mesh="coupler"/>
                          </body>
                        </body>
                        <body name="left_spring_link_1" pos="0 -0.0132 0.0609" quat="0 0 0 1">
                          <inertial mass="0.0221642" pos="-8.65005e-09 0.0181624 0.0212658"
                            quat="0.663403 -0.244737 0.244737 0.663403"
                            diaginertia="8.96853e-06 6.71733e-06 2.63931e-06"/>
                          <joint name="left_spring_link_joint_1" class="spring_link"/>
                          <geom class="2f85/collision" mesh="spring_link"/>
                          <body name="left_follower_1" pos="0 0.055 0.0375">
                            <inertial mass="0.0125222" pos="0 -0.011046 0.0124786" quat="1 0.1664 0 0"
                              diaginertia="2.67415e-06 2.4559e-06 6.02031e-07"/>
                            <joint name="left_follower_joint_1" class="follower"/>
                            <geom class="2f85/collision" mesh="follower"/>
                            <body name="left_pad_1" pos="0 -0.0189 0.01352">
                              <geom class="pad_box1" name="left_pad1_1"/>
                              <geom class="pad_box2" name="left_pad2_1"/>
                              <inertial mass="0.0035" pos="0 -0.0025 0.0185" quat="1 0 0 1"
                                diaginertia="4.73958e-07 3.64583e-07 1.23958e-07"/>
                            </body>
                          </body>
                        </body>
                      </body>
                    </body>
                  </body>
                </body>
              </body>
            </body>
          </body>
        </body>
      </body>
    </body>

    <!-- Robot 2 (offset by 2m in X) -->
    <body name="ur5e_2/base" pos="2 0 0" quat="1 0 0 1" childclass="ur5e">
      <inertial mass="4" pos="0 0 0" diaginertia="0.00443333156 0.00443333156 0.0072"/>
      <geom mesh="base_0" material="black" class="visual"/>
      <geom mesh="base_1" material="jointgray" class="visual"/>
      <body name="shoulder_link_2" pos="0 0 0.163">
        <inertial mass="3.7" pos="0 0 0" diaginertia="0.0102675 0.0102675 0.00666"/>
        <joint name="shoulder_pan_joint_2" axis="0 0 1"/>
        <geom class="collision" size="0.06 0.06" pos="0 0 -0.04"/>
        <body name="upper_arm_link_2" pos="0 0.138 0" quat="1 0 1 0">
          <inertial mass="8.393" pos="0 0 0.2125" diaginertia="0.133886 0.133886 0.0151074"/>
          <joint name="shoulder_lift_joint_2"/>
          <geom class="collision" pos="0 -0.04 0" quat="1 1 0 0" size="0.06 0.06"/>
          <geom class="collision" size="0.05 0.2" pos="0 0 0.2"/>
          <body name="forearm_link_2" pos="0 -0.131 0.425">
            <inertial mass="2.275" pos="0 0 0.196" diaginertia="0.0311796 0.0311796 0.004095"/>
            <joint name="elbow_joint_2" class="joint_limited"/>
            <geom class="collision" pos="0 0.08 0" quat="1 1 0 0" size="0.055 0.06"/>
            <geom class="collision" size="0.038 0.19" pos="0 0 0.2"/>
            <body name="wrist_1_link_2" pos="0 0 0.392" quat="1 0 1 0">
              <inertial mass="1.219" pos="0 0.127 0" diaginertia="0.0025599 0.0025599 0.0021942"/>
              <joint name="wrist_1_joint_2"/>
              <geom class="collision" pos="0 0.05 0" quat="1 1 0 0" size="0.04 0.07"/>
              <body name="wrist_2_link_2" pos="0 0.127 0">
                <inertial mass="1.219" pos="0 0 0.1" diaginertia="0.0025599 0.0025599 0.0021942"/>
                <joint name="wrist_2_joint_2" axis="0 0 1"/>
                <geom class="collision" size="0.04 0.06" pos="0 0 0.04"/>
                <geom class="collision" pos="0 0.02 0.1" quat="1 1 0 0" size="0.04 0.04"/>
                <body name="wrist_3_link_2" pos="0 0 0.1">
                  <inertial mass="0.1879" pos="0 0.0771683 0" quat="1 0 0 1"
                    diaginertia="0.000132134 9.90863e-05 9.90863e-05"/>
                  <joint name="wrist_3_joint_2"/>
                  <geom class="eef_collision" pos="0 0.08 0" quat="1 1 0 0" size="0.04 0.02"/>
                  <body name="attachment_2" pos="0 0.1 0" quat="-1 1 1 1">
                    <body name="base_mount_2" quat="1 0 0 1" childclass="2f85">
                      <geom class="2f85/collision" mesh="base_mount"/>
                      <body name="gripper_base_2" pos="0 0 0.0038" quat="1 0 0 -1">
                        <inertial mass="0.777441" pos="0 -2.70394e-05 0.0354675" quat="1 -0.00152849 0 0"
                          diaginertia="0.000260285 0.000225381 0.000152708"/>
                        <geom class="2f85/collision" mesh="base"/>
                        <body name="right_driver_2" pos="0 0.0306011 0.054904">
                          <inertial mass="0.00899563" pos="2.96931e-12 0.0177547 0.00107314"
                            quat="0.681301 0.732003 0 0" diaginertia="1.72352e-06 1.60906e-06 3.22006e-07"/>
                          <joint name="right_driver_joint_2" class="driver"/>
                          <geom class="2f85/collision" mesh="driver"/>
                          <body name="right_coupler_2" pos="0 0.0315 -0.0041">
                            <inertial mass="0.0140974" pos="0 0.00301209 0.0232175"
                              quat="0.705636 -0.0455904 0.0455904 0.705636"
                              diaginertia="4.16206e-06 3.52216e-06 8.88131e-07"/>
                            <joint name="right_coupler_joint_2" class="coupler"/>
                            <geom class="2f85/collision" mesh="coupler"/>
                          </body>
                        </body>
                        <body name="right_spring_link_2" pos="0 0.0132 0.0609">
                          <inertial mass="0.0221642" pos="-8.65005e-09 0.0181624 0.0212658"
                            quat="0.663403 -0.244737 0.244737 0.663403"
                            diaginertia="8.96853e-06 6.71733e-06 2.63931e-06"/>
                          <joint name="right_spring_link_joint_2" class="spring_link"/>
                          <geom class="2f85/collision" mesh="spring_link"/>
                          <body name="right_follower_2" pos="0 0.055 0.0375">
                            <inertial mass="0.0125222" pos="0 -0.011046 0.0124786" quat="1 0.1664 0 0"
                              diaginertia="2.67415e-06 2.4559e-06 6.02031e-07"/>
                            <joint name="right_follower_joint_2" class="follower"/>
                            <geom class="2f85/collision" mesh="follower"/>
                            <body name="right_pad_2" pos="0 -0.0189 0.01352">
                              <geom class="pad_box1" name="right_pad1_2"/>
                              <geom class="pad_box2" name="right_pad2_2"/>
                              <inertial mass="0.0035" pos="0 -0.0025 0.0185" quat="0.707107 0 0 0.707107"
                                diaginertia="4.73958e-07 3.64583e-07 1.23958e-07"/>
                            </body>
                          </body>
                        </body>
                        <body name="left_driver_2" pos="0 -0.0306011 0.054904" quat="0 0 0 1">
                          <inertial mass="0.00899563" pos="0 0.0177547 0.00107314" quat="0.681301 0.732003 0 0"
                            diaginertia="1.72352e-06 1.60906e-06 3.22006e-07"/>
                          <joint name="left_driver_joint_2" class="driver"/>
                          <geom class="2f85/collision" mesh="driver"/>
                          <body name="left_coupler_2" pos="0 0.0315 -0.0041">
                            <inertial mass="0.0140974" pos="0 0.00301209 0.0232175"
                              quat="0.705636 -0.0455904 0.0455904 0.705636"
                              diaginertia="4.16206e-06 3.52216e-06 8.88131e-07"/>
                            <joint name="left_coupler_joint_2" class="coupler"/>
                            <geom class="2f85/collision" mesh="coupler"/>
                          </body>
                        </body>
                        <body name="left_spring_link_2" pos="0 -0.0132 0.0609" quat="0 0 0 1">
                          <inertial mass="0.0221642" pos="-8.65005e-09 0.0181624 0.0212658"
                            quat="0.663403 -0.244737 0.244737 0.663403"
                            diaginertia="8.96853e-06 6.71733e-06 2.63931e-06"/>
                          <joint name="left_spring_link_joint_2" class="spring_link"/>
                          <geom class="2f85/collision" mesh="spring_link"/>
                          <body name="left_follower_2" pos="0 0.055 0.0375">
                            <inertial mass="0.0125222" pos="0 -0.011046 0.0124786" quat="1 0.1664 0 0"
                              diaginertia="2.67415e-06 2.4559e-06 6.02031e-07"/>
                            <joint name="left_follower_joint_2" class="follower"/>
                            <geom class="2f85/collision" mesh="follower"/>
                            <body name="left_pad_2" pos="0 -0.0189 0.01352">
                              <geom class="pad_box1" name="left_pad1_2"/>
                              <geom class="pad_box2" name="left_pad2_2"/>
                              <inertial mass="0.0035" pos="0 -0.0025 0.0185" quat="1 0 0 1"
                                diaginertia="4.73958e-07 3.64583e-07 1.23958e-07"/>
                            </body>
                          </body>
                        </body>
                      </body>
                    </body>
                  </body>
                </body>
              </body>
            </body>
          </body>
        </body>
      </body>
    </body>
  </worldbody>

  <contact>
    <!-- Robot 1 -->
    <exclude body1="gripper_base_1" body2="left_driver_1"/>
    <exclude body1="gripper_base_1" body2="right_driver_1"/>
    <exclude body1="gripper_base_1" body2="left_spring_link_1"/>
    <exclude body1="gripper_base_1" body2="right_spring_link_1"/>
    <exclude body1="right_coupler_1" body2="right_follower_1"/>
    <exclude body1="left_coupler_1" body2="left_follower_1"/>
    <!-- Robot 2 -->
    <exclude body1="gripper_base_2" body2="left_driver_2"/>
    <exclude body1="gripper_base_2" body2="right_driver_2"/>
    <exclude body1="gripper_base_2" body2="left_spring_link_2"/>
    <exclude body1="gripper_base_2" body2="right_spring_link_2"/>
    <exclude body1="right_coupler_2" body2="right_follower_2"/>
    <exclude body1="left_coupler_2" body2="left_follower_2"/>
  </contact>

  <tendon>
    <fixed name="split_1">
      <joint joint="right_driver_joint_1" coef="0.5"/>
      <joint joint="left_driver_joint_1" coef="0.5"/>
    </fixed>
    <fixed name="split_2">
      <joint joint="right_driver_joint_2" coef="0.5"/>
      <joint joint="left_driver_joint_2" coef="0.5"/>
    </fixed>
  </tendon>

  <equality>
    <!-- Robot 1 -->
    <connect anchor="0 0 0" body1="right_follower_1" body2="right_coupler_1" solimp="0.95 0.99 0.001" solref="0.005 1"/>
    <connect anchor="0 0 0" body1="left_follower_1" body2="left_coupler_1" solimp="0.95 0.99 0.001" solref="0.005 1"/>
    <joint joint1="right_driver_joint_1" joint2="left_driver_joint_1" polycoef="0 1 0 0 0" solimp="0.95 0.99 0.001"
      solref="0.005 1"/>
    <!-- Robot 2 -->
    <connect anchor="0 0 0" body1="right_follower_2" body2="right_coupler_2" solimp="0.95 0.99 0.001" solref="0.005 1"/>
    <connect anchor="0 0 0" body1="left_follower_2" body2="left_coupler_2" solimp="0.95 0.99 0.001" solref="0.005 1"/>
    <joint joint1="right_driver_joint_2" joint2="left_driver_joint_2" polycoef="0 1 0 0 0" solimp="0.95 0.99 0.001"
      solref="0.005 1"/>
  </equality>

  <actuator>
    <!-- Robot 1 -->
    <position class="position" name="shoulder_pan_position_1" joint="shoulder_pan_joint_1"/>
    <position class="position" name="shoulder_lift_position_1" joint="shoulder_lift_joint_1"/>
    <position class="position_limited" name="elbow_position_1" joint="elbow_joint_1"/>
    <position class="position_small" name="wrist_1_position_1" joint="wrist_1_joint_1"/>
    <position class="position_small" name="wrist_2_position_1" joint="wrist_2_joint_1"/>
    <position class="position_small" name="wrist_3_position_1" joint="wrist_3_joint_1"/>
    <general class="2f85" name="fingers_actuator_1" tendon="split_1" forcerange="-5 5" ctrlrange="0 1" gainprm="80 0 0"
      biasprm="0 -100 -10"/>
    <!-- Robot 2 -->
    <position class="position" name="shoulder_pan_position_2" joint="shoulder_pan_joint_2"/>
    <position class="position" name="shoulder_lift_position_2" joint="shoulder_lift_joint_2"/>
    <position class="position_limited" name="elbow_position_2" joint="elbow_joint_2"/>
    <position class="position_small" name="wrist_1_position_2" joint="wrist_1_joint_2"/>
    <position class="position_small" name="wrist_2_position_2" joint="wrist_2_joint_2"/>
    <position class="position_small" name="wrist_3_position_2" joint="wrist_3_joint_2"/>
    <general class="2f85" name="fingers_actuator_2" tendon="split_2" forcerange="-5 5" ctrlrange="0 1" gainprm="80 0 0"
      biasprm="0 -100 -10"/>
  </actuator>
</mujoco>
